Workbook
Name UPDATE: 'Data Sheet >'!$E$1

Sheet Teaser
B2: ='Data Sheet >'!B1&" - One Page Profile" -> INFOSYS LTD - One Page Profile
C4: ='Input Sheet'!C3 -> With over four decades of experience in managing the systems and workings of global enterprises, we expertly steer clients, in 59 countries, as they navigate their digital transformation powered by cloud and AI. We enable them with an AI-first core, empower the business with agile digital at scale and drive continuous improvement with always-on learning through the transfer of digital skills, expertise, and ideas from our innovation ecosystem.
B5: INR (Crs)
B6: Key Financial Metrics | C6: ='Data Sheet >'!G16 -> 44651 | D6: ='Data Sheet >'!H16 -> 45016 | E6: ='Data Sheet >'!I16 -> 45382 | F6: ='Data Sheet >'!J16 -> 45747 | G6: ='Data Sheet >'!K16 -> 46112 | I6: Share Price - 5 Year
B8: Total Sales | C8: ='Data Sheet >'!G17 -> 121641 | D8: ='Data Sheet >'!H17 -> 146767 | E8: ='Data Sheet >'!I17 -> 153670 | F8: ='Data Sheet >'!J17 -> 162990 | G8: ='Data Sheet >'!K17 -> 178650
B9: Sales Growth (y-o-y) | C9: ='Data Sheet >'!G17/'Data Sheet >'!F17-1 -> 0.21069552 | D9: ='Data Sheet >'!H17/'Data Sheet >'!G17-1 -> 0.20655864 | E9: ='Data Sheet >'!I17/'Data Sheet >'!H17-1 -> 0.047033734 | F9: ='Data Sheet >'!J17/'Data Sheet >'!I17-1 -> 0.060649444 | G9: ='Data Sheet >'!K17/'Data Sheet >'!J17-1 -> 0.096079514
B10: Gross Profit Margins (%) | C10: ='Income Statement '!C12 -> 0.82882416 | D10: ='Income Statement '!D12 -> 0.81940082 | E10: ='Income Statement '!E12 -> 0.82173489 | F10: ='Income Statement '!F12 -> 0.81215412 | G10: ='Income Statement '!G12 -> 0.81446963
B11: EBITDA Margins (%) | C11: ='Income Statement '!C18 -> 0.25888475 | D11: ='Income Statement '!D18 -> 0.23935898 | E11: ='Income Statement '!E18 -> 0.2370339 | F11: ='Income Statement '!F18 -> 0.24072642 | G11: ='Income Statement '!G18 -> 0.23666387
B12: EBIT Margins (%) | C12: ='Income Statement '!C24 -> 0.23030886 | D12: ='Income Statement '!D24 -> 0.21057186 | E12: ='Income Statement '!E24 -> 0.20659205 | F12: ='Income Statement '!F24 -> 0.21120314 | G12: ='Income Statement '!G24 -> 0.20922474
B13: Net Profit Margins (%) | C13: ='Income Statement '!C36 -> 0.16319333 | D13: ='Income Statement '!D36 -> 0.14585704 | E13: ='Income Statement '!E36 -> 0.14015097 | F13: ='Income Statement '!F36 -> 0.14203325 | G13: ='Income Statement '!G36 -> 0.14800448
B14: Earning Per Share (In Rs) | C14: ='Income Statement '!C40 -> 47.189008 | D14: ='Income Statement '!D40 -> 51.60054 | E14: ='Income Statement '!E40 -> 51.885133 | F14: ='Income Statement '!F40 -> 55.73881 | G14: ='Income Statement '!G40 -> 65.196272
B15: EPS Growth (y-o-y) | C15: ='Profit & Loss'!G13/'Profit & Loss'!F13-1 -> 0.15724348 | D15: ='Profit & Loss'!H13/'Profit & Loss'!G13-1 -> 0.10504043 | E15: ='Profit & Loss'!I13/'Profit & Loss'!H13-1 -> 0.088128839 | F15: ='Profit & Loss'!J13/'Profit & Loss'!I13-1 -> 0.017709137 | G15: ='Profit & Loss'!K13/'Profit & Loss'!J13-1 -> 0.12863452
B16: Dividend Per Share (In Rs) | C16: ='Income Statement '!C43 -> 30.92115 | D16: ='Income Statement '!D43 -> 33.913127 | E16: ='Income Statement '!E43 -> 45.901371 | F16: ='Income Statement '!F43 -> 42.924422 | G16: ='Income Statement '!G43 -> 47.91005
B17: DSP Growth (y-o-y) | C17: ='Profit & Loss'!G29 -> 0.14865158 | D17: ='Profit & Loss'!H29 -> 0.096761529 | E17: ='Profit & Loss'!I29 -> 0.35349861 | F17: ='Profit & Loss'!J29 -> -0.064855345 | G17: ='Profit & Loss'!K29 -> 0.116149
B19: Key Financial Ratios | C19: =C6 -> 44651 | D19: =D6 -> 45016 | E19: =E6 -> 45382 | F19: =F6 -> 45747 | G19: =G6 -> 46112 | I19: Volume - 5 Year
B21: Price to Earning | C21: ='Profit & Loss'!G14 -> 36.280171 | D21: ='Profit & Loss'!H14 -> 24.585986 | E21: ='Profit & Loss'!I14 -> 23.703944 | F21: ='Profit & Loss'!J14 -> 24.420247 | G21: ='Profit & Loss'!K14 -> 17.228035
B22: EV/EBITDA | C22: ='Profit & Loss'!G35 -> 25.091505 | D22: ='Profit & Loss'!H35 -> 16.752785 | E22: ='Profit & Loss'!I35 -> 16.894951 | F22: ='Profit & Loss'!J35 -> 16.212409 | G22: ='Profit & Loss'!K35 -> 11.687993
B23: EV/Sales | C23: ='Profit & Loss'!G36 -> 6.4958081 | D23: ='Profit & Loss'!H36 -> 4.0099296 | E23: ='Profit & Loss'!I36 -> 4.0046761 | F23: ='Profit & Loss'!J36 -> 3.9027552 | G23: ='Profit & Loss'!K36 -> 2.7661256
B24: Price to Book Value | C24: ='Profit & Loss'!G37 -> 10.645715 | D24: ='Profit & Loss'!H37 -> 7.8560258 | E24: ='Profit & Loss'!I37 -> 7.0568974 | F24: ='Profit & Loss'!J37 -> 6.8080952 | G24: ='Profit & Loss'!K37 -> 5.4623846
B25: Return on Equity (%) | C25: ='His Balance Sheet'!G23 -> 0.29343066 | D25: ='His Balance Sheet'!H23 -> 0.31953267 | E25: ='His Balance Sheet'!I23 -> 0.29770984 | F25: ='His Balance Sheet'!J23 -> 0.27878895 | G25: ='His Balance Sheet'!K23 -> 0.31706371
B26: Return oc Capital Employed | C26: ='His Balance Sheet'!G24 -> 0.37304615 | D26: ='His Balance Sheet'!H24 -> 0.40850909 | E26: ='His Balance Sheet'!I24 -> 0.40468196 | F26: ='His Balance Sheet'!J24 -> 0.37925394 | G26: ='His Balance Sheet'!K24 -> 0.39220082
B28: ='Input Sheet'!B11 -> Shareholder's name | C28: ='Input Sheet'!C11 -> No. of Share (in crs) | D28: ='Input Sheet'!D11 -> Shareholding (%) | E28: ='Input Sheet'!E11 -> Market Value (in crs) | G28: Shareholding Pattern
B30: ='Input Sheet'!B12 -> LIFE INSURANCE CORPORATION OF INDIA - ULIF00220091 | C30: ='Input Sheet'!C12 -> 43.859487 | D30: ='Input Sheet'!D12 -> 0.118 | E30: ='Input Sheet'!E12 -> 50613.848
B31: ='Input Sheet'!B13 -> SBI MUTUAL FUND | C31: ='Input Sheet'!C13 -> 16.748512 | D31: ='Input Sheet'!D13 -> 0.0451 | E31: ='Input Sheet'!E13 -> 19327.783
B32: ='Input Sheet'!B14 -> ICICI PRUDENTIAL MUTUAL FUND | C32: ='Input Sheet'!C14 -> 14.669216 | D32: ='Input Sheet'!D14 -> 0.0395 | E32: ='Input Sheet'!E14 -> 16928.275
B33: ='Input Sheet'!B15 -> National Pension System Trust | C33: ='Input Sheet'!C15 -> 12.570505 | D33: ='Input Sheet'!D15 -> 0.0338 | E33: ='Input Sheet'!E15 -> 14506.362
B34: ='Input Sheet'!B16 -> NIPPON LIFE INDIA TRUSTEE | C34: ='Input Sheet'!C16 -> 9.8562135 | D34: ='Input Sheet'!D16 -> 0.0265 | E34: ='Input Sheet'!E16 -> 11374.07
B35: ='Input Sheet'!B17 -> SUDHA GOPALAKRISHNAN | C35: ='Input Sheet'!C17 -> 9.5357 | D35: ='Input Sheet'!D17 -> 0.0257 | E35: ='Input Sheet'!E17 -> 11004.198
B36: ='Input Sheet'!B18 -> UTI MUTUAL FUND | C36: ='Input Sheet'!C18 -> 7.188733 | D36: ='Input Sheet'!D18 -> 0.0193 | E36: ='Input Sheet'!E18 -> 8295.7979
B37: ='Input Sheet'!B19 -> HDFC MUTUAL FUND | C37: ='Input Sheet'!C19 -> 6.3538616 | D37: ='Input Sheet'!D19 -> 0.0171 | E37: ='Input Sheet'!E19 -> 7332.3563
B38: ='Input Sheet'!B20 -> ROHAN MURTY | C38: ='Input Sheet'!C20 -> 6.0812892 | D38: ='Input Sheet'!D20 -> 0.0164 | E38: ='Input Sheet'!E20 -> 7017.8077
B39: ='Input Sheet'!B21 -> VANGUARD TOTAL INTERNATIONAL STOCK INDEX FUND | C39: ='Input Sheet'!C21 -> 5.2268865 | D39: ='Input Sheet'!D21 -> 0.0141 | E39: ='Input Sheet'!E21 -> 6031.827
B41: Managerial Remuneration | C41: Designation | E41: % Change | F41: X of Median Salary | I41: Capital Structure
B43: Nandan M. Nilekani | C43: Chairman | E43: - | F43: - | I43: Share Price | K43: ='Data Sheet >'!B8 -> 1013.85
B44: Salil Parekh | C44: CEO & MD | E44: 22 | F44: 752:1 | I44: Number of Shares o/s | K44: ='Data Sheet >'!B6 -> 406.22571
B45: Jayesh Sanghrajka | C45: CFO | E45: - | F45: 85:1 | I45: Market Capitalization | K45: =K43*K44 -> 411851.94
B46: A.G.S. Manikantha | C46: Company Secretary | E46: -4 | F46: 13:1 | I46: Less: Cash & Equivalents | K46: =-'Data Sheet >'!K69 -> -22201
I47: Add: Total Debt | K47: ='Data Sheet >'!K59 -> 9176
I48: Add: Minority Interest | K48: 466
I49: Enterprise Value | K49: =SUM(K45:K48) -> 399292.94
...

Sheet Input Sheet
B3: Assumption Drivers | C3: With over four decades of experience in managing the systems and workings of global enterprises, we expertly steer clients, in 59 countries, as they navigate their digital transformation powered by cloud and AI. We enable them with an AI-first core, empower the business with agile digital at scale and drive continuous improvement with always-on learning through the transfer of digital skills, expertise, and ideas from our innovation ecosystem. | M3: Date | N3: Adj Close | O3: Volume
M4: Oct 22, 2026 | N4: 13.12 | O4: 22668585
M5: Oct 21, 2026 | N5: 12.75 | O5: 22042900
M6: Oct 20, 2026 | N6: 12.66 | O6: 22799200
M7: Oct 19, 2026 | N7: 12.2 | O7: 20804200
M8: Oct 16, 2026 | N8: 12.24 | O8: 17932300
M9: Oct 15, 2026 | N9: 12.13 | O9: 29560200
C10: 100 | M10: Oct 14, 2026 | N10: 11.48 | O10: 14209400
B11: Shareholder's name | C11: No. of Share (in crs) | D11: Shareholding (%) | E11: Market Value (in crs) | M11: Oct 13, 2026 | N11: 11.4 | O11: 25564500
B12: LIFE INSURANCE CORPORATION OF INDIA - ULIF00220091 | C12: 43.859487 | D12: 0.118 | E12: =1154*C12 -> 50613.848 | M12: Oct 12, 2026 | N12: 10.83 | O12: 13025600
B13: SBI MUTUAL FUND | C13: 16.748512 | D13: 0.0451 | E13: =1154*C13 -> 19327.783 | M13: Oct 09, 2026 | N13: 10.73 | O13: 12902100
B14: ICICI PRUDENTIAL MUTUAL FUND | C14: 14.669216 | D14: 0.0395 | E14: =1154*C14 -> 16928.275 | M14: Oct 08, 2026 | N14: 10.7 | O14: 31359300
B15: National Pension System Trust | C15: 12.570505 | D15: 0.0338 | E15: =1154*C15 -> 14506.362 | M15: Oct 07, 2026 | N15: 10.55 | O15: 28397400
B16: NIPPON LIFE INDIA TRUSTEE | C16: 9.8562135 | D16: 0.0265 | E16: =1154*C16 -> 11374.07 | M16: Oct 06, 2026 | N16: 10.55 | O16: 20107800
B17: SUDHA GOPALAKRISHNAN | C17: 9.5357 | D17: 0.0257 | E17: =1154*C17 -> 11004.198 | M17: Oct 05, 2026 | N17: 10.76 | O17: 17223000
B18: UTI MUTUAL FUND | C18: 7.188733 | D18: 0.0193 | E18: =1154*C18 -> 8295.7979 | M18: Oct 02, 2026 | N18: 11.04 | O18: 19592500
B19: HDFC MUTUAL FUND | C19: 6.3538616 | D19: 0.0171 | E19: =1154*C19 -> 7332.3563 | M19: Oct 01, 2026 | N19: 11.35 | O19: 38330500
B20: ROHAN MURTY | C20: 6.0812892 | D20: 0.0164 | E20: =1154*C20 -> 7017.8077 | M20: Sep 30, 2026 | N20: 10.76 | O20: 20322700
B21: VANGUARD TOTAL INTERNATIONAL STOCK INDEX FUND | C21: 5.2268865 | D21: 0.0141 | E21: =1154*C21 -> 6031.827 | M21: Sep 29, 2026 | N21: 10.64 | O21: 14285700
M22: Sep 28, 2026 | N22: 10.52 | O22: 13014600
M23: Sep 25, 2026 | N23: 10.5 | O23: 17570900
B24: Promoters | C24: 0.139 | M24: Sep 24, 2026 | N24: 10.5 | O24: 14511200
B25: FIIs | C25: 0.2744 | M25: Sep 23, 2026 | N25: 10.75 | O25: 17357500
B26: DIIs | C26: 0.4266 | M26: Sep 22, 2026 | N26: 10.76 | O26: 17671200
B27: Public | C27: 0.1559 | M27: Sep 21, 2026 | N27: 10.89 | O27: 9680900
B28: Government | C28: 0.0021 | M28: Sep 18, 2026 | N28: 10.82 | O28: 17157100
M29: Sep 17, 2026 | N29: 11.07 | O29: 9199200
M30: Sep 16, 2026 | N30: 11.08 | O30: 11497600
M31: Sep 15, 2026 | N31: 11.32 | O31: 17333900
M32: Sep 14, 2026 | N32: 11.6 | O32: 24835300
M33: Sep 11, 2026 | N33: 11.07 | O33: 16797600
M34: Sep 10, 2026 | N34: 10.91 | O34: 14030500
M35: Sep 09, 2026 | N35: 10.93 | O35: 17975200
M36: Sep 08, 2026 | N36: 11.13 | O36: 20180800
M37: Sep 04, 2026 | N37: 11.7 | O37: 19837900
M38: Sep 03, 2026 | N38: 12.09 | O38: 11957100
M39: Sep 02, 2026 | N39: 11.97 | O39: 11007700
M40: Sep 01, 2026 | N40: 12 | O40: 16393700
... M1257: Oct 25, 2021 | N1257: 19.96 | O1257: 10860000

Sheet Dupont Analysis
B3: ='Data Sheet >'!A1 -> INFOSYS LTD
B4: =CONCATENATE(" ","(",VLOOKUP(B3,'List of Stocks'!B2:E5442,3,1)," | ","BSE Code: ",VLOOKUP(B3,'List of Stocks'!B2:E5442,2,1),")") -> (INFY | BSE Code: 500209)
B5: =CONCATENATE(" ","INR "&'Data Sheet >'!B8) -> INR 1013.85
B6: 52 Week (High - INR 1728.00 & Low - 980.40)
B8: About the Company
B9: Infosys Limited is an Indian multinational IT services and consulting company founded in 1981. Its headquarters is located in Bengaluru, Karnataka, India. The company provides services such as software development, IT consulting, cloud computing, artificial intelligence, data analytics, and digital transformation. Infosys serves clients across various industries, including banking, financial services, insurance, retail, manufacturing, and healthcare. It operates in numerous countries and generates revenue by providing technology solutions and business services to organisations worldwide. Infosys is listed on the National Stock Exchange (NSE) and Bombay Stock Exchange (BSE) in India, as well as the New York Stock Exchange (NYSE) in the United States. It is recognised as one of India's leading IT companies and plays a significant role in the global technology industry.
B18: Financial Summary
B76: Return on Equity (ROE)
D77: ='Data Sheet >'!G16 -> 44651 | E77: ='Data Sheet >'!H16 -> 45016 | F77: ='Data Sheet >'!I16 -> 45382 | G77: ='Data Sheet >'!J16 -> 45747 | H77: ='Data Sheet >'!K16 -> 46112
B78: Net Profit | D78: ='Data Sheet >'!G30 -> 22110 | E78: ='Data Sheet >'!H30 -> 24095 | F78: ='Data Sheet >'!I30 -> 26233 | G78: ='Data Sheet >'!J30 -> 26713 | H78: ='Data Sheet >'!K30 -> 29440
B79: Average Shareholder Equity | D79: =(('Data Sheet >'!G57+'Data Sheet >'!G58)+('Data Sheet >'!F57+'Data Sheet >'!F58))/2 -> 75850.5 | E79: =(('Data Sheet >'!H57+'Data Sheet >'!H58)+('Data Sheet >'!G57+'Data Sheet >'!G58))/2 -> 75378.5 | F79: =(('Data Sheet >'!I57+'Data Sheet >'!I58)+('Data Sheet >'!H57+'Data Sheet >'!H58))/2 -> 81761.5 | G79: =(('Data Sheet >'!J57+'Data Sheet >'!J58)+('Data Sheet >'!I57+'Data Sheet >'!I58))/2 -> 91967 | H79: =(('Data Sheet >'!K57+'Data Sheet >'!K58)+('Data Sheet >'!J57+'Data Sheet >'!J58))/2 -> 94335
B80: Return on Equity (ROE) | D80: =D78/D79 -> 0.29149445 | E80: =E78/E79 -> 0.31965348 | F80: =F78/F79 -> 0.32084783 | G80: =G78/G79 -> 0.29046288 | H80: =H78/H79 -> 0.31207929
B82: ROE - Dupont Equation
D83: =D77 -> 44651 | E83: =E77 -> 45016 | F83: =F77 -> 45382 | G83: =G77 -> 45747 | H83: =H77 -> 46112
B84: =B78 -> Net Profit | D84: =D78 -> 22110 | E84: =E78 -> 24095 | F84: =F78 -> 26233 | G84: =G78 -> 26713 | H84: =H78 -> 29440
B85: Revenue | D85: ='Data Sheet >'!G17 -> 121641 | E85: ='Data Sheet >'!H17 -> 146767 | F85: ='Data Sheet >'!I17 -> 153670 | G85: ='Data Sheet >'!J17 -> 162990 | H85: ='Data Sheet >'!K17 -> 178650
B86: Net Profit Margin (A) | D86: =D84/D85 -> 0.18176437 | E86: =E84/E85 -> 0.16417178 | F86: =F84/F85 -> 0.17070996 | G86: =G84/G85 -> 0.16389349 | H86: =H84/H85 -> 0.16479149
B88: Revenue | D88: =D85 -> 121641 | E88: =E85 -> 146767 | F88: =F85 -> 153670 | G88: =G85 -> 162990 | H88: =H85 -> 178650
B89: Average Total Assets | D89: =('Data Sheet >'!G66+'Data Sheet >'!F66)/2 -> 112120 | E89: =('Data Sheet >'!H66+'Data Sheet >'!G66)/2 -> 120662.5 | F89: =('Data Sheet >'!I66+'Data Sheet >'!H66)/2 -> 130308 | G89: =('Data Sheet >'!J66+'Data Sheet >'!I66)/2 -> 141907.5 | H89: =('Data Sheet >'!K66+'Data Sheet >'!J66)/2 -> 151041.5
B90: Assets Turnover Ratio (B) | D90: =D88/D89 -> 1.0849179 | E90: =E88/E89 -> 1.2163431 | F90: =F88/F89 -> 1.1792829 | G90: =G88/G89 -> 1.1485651 | H90: =H88/H89 -> 1.1827875
B92: =B89 -> Average Total Assets | D92: =D89 -> 112120 | E92: =E89 -> 120662.5 | F92: =F89 -> 130308 | G92: =G89 -> 141907.5 | H92: =H89 -> 151041.5
B93: =B79 -> Average Shareholder Equity | D93: =D79 -> 75850.5 | E93: =E79 -> 75378.5 | F93: =F79 -> 81761.5 | G93: =G79 -> 91967 | H93: =H79 -> 94335
B94: Equity Multiplier (C) | D94: =D92/D93 -> 1.4781709 | E94: =E92/E93 -> 1.6007549 | F94: =F92/F93 -> 1.5937575 | G94: =G92/G93 -> 1.5430263 | H94: =H92/H93 -> 1.6011184
B96: Return on Equity (A*B*C) | D96: =D94*D90*D86 -> 0.29149445 | E96: =E94*E90*E86 -> 0.31965348 | F96: =F94*F90*F86 -> 0.32084783 | G96: =G94*G90*G86 -> 0.29046288 | H96: =H94*H90*H86 -> 0.31207929
B98: Return on Equity Assets
D99: =D77 -> 44651 | E99: =E77 -> 45016 | F99: =F77 -> 45382 | G99: =G77 -> 45747 | H99: =H77 -> 46112
B100: Net Profit | D100: =D78 -> 22110 | E100: =E78 -> 24095 | F100: =F78 -> 26233 | G100: =G78 -> 26713 | H100: =H78 -> 29440
B101: =B92 -> Average Total Assets | D101: =D89 -> 112120 | E101: =E89 -> 120662.5 | F101: =F89 -> 130308 | G101: =G89 -> 141907.5 | H101: =H89 -> 151041.5
B102: Return on Assets (ROA) | D102: =D100/D101 -> 0.19719943 | E102: =E100/E101 -> 0.19968922 | F102: =F100/F101 -> 0.20131535 | G102: =G100/G101 -> 0.18824234 | H102: =H100/H101 -> 0.19491332
B104: ROA - Dupont Equation
D105: =D99 -> 44651 | E105: =E99 -> 45016 | F105: =F99 -> 45382 | G105: =G99 -> 45747 | H105: =H99 -> 46112
B106: =B100 -> Net Profit | D106: =D100 -> 22110 | E106: =E100 -> 24095 | F106: =F100 -> 26233 | G106: =G100 -> 26713 | H106: =H100 -> 29440
B107: Revenue | D107: =D85 -> 121641 | E107: =E85 -> 146767 | F107: =F85 -> 153670 | G107: =G85 -> 162990 | H107: =H85 -> 178650
B108: Net Profit Margin (A) | D108: =D106/D107 -> 0.18176437 | E108: =E106/E107 -> 0.16417178 | F108: =F106/F107 -> 0.17070996 | G108: =G106/G107 -> 0.16389349 | H108: =H106/H107 -> 0.16479149
B110: Revenue | D110: =D107 -> 121641 | E110: =E107 -> 146767 | F110: =F107 -> 153670 | G110: =G107 -> 162990 | H110: =H107 -> 178650
B111: Average Total Assets | D111: =D101 -> 112120 | E111: =E101 -> 120662.5 | F111: =F101 -> 130308 | G111: =G101 -> 141907.5 | H111: =H101 -> 151041.5
B112: Assets Turnover Ratio (B) | D112: =D110/D111 -> 1.0849179 | E112: =E110/E111 -> 1.2163431 | F112: =F110/F111 -> 1.1792829 | G112: =G110/G111 -> 1.1485651 | H112: =H110/H111 -> 1.1827875
B114: Return on Assets (A*B) | D114: =D112*D108 -> 0.19719943 | E114: =E112*E108 -> 0.19968922 | F114: =F112*F108 -> 0.20131535 | G114: =G112*G108 -> 0.18824234 | H114: =H112*H108 -> 0.19491332

Sheet List of Stocks
B2: COMPANY_NAME | C2: BSE | D2: NSE | E2: Industry
B3: 20 MICRONS LTD | C3: 533022 | D3: 20MICRONS | E3: Mining
B4: 21ST CENTURY MANAGEMENT SERVICES LTD | C4: 526921 | D4: 21STCENMGM | E4: Other Financial Services
B5: 3I INFOTECH LTD | C5: 532628 | D5: 3IINFOTECH | E5: IT Consulting & Software
B6: 3M (INDIA) LTD | C6: 523395 | D6: 3M(INDIA) | E6: Diversified
B7: 3M INDIA LTD | C7: 523395 | D7: 3MINDIA | E7: Diversified
B8: 3P LAND HOLDINGS LTD | C8: 516092 | D8: 3PLAND | E8: Paper & Paper Products
B9: 5PAISA CAPITAL LTD | C9: 540776 | D9: 5PAISA | E9: Other Financial Services
B10: 63 MOONS TECHNOLOGIES LTD | C10: 526881 | D10: 63MOONS | E10: IT Consulting & Software
B11: 7NR RETAIL LTD | C11: 540615 | D11: Not Listed | E11: Specialty Retail
B12: 7SEAS ENTERTAINMENT LTD | C12: 540874 | D12: Not Listed | E12: Movies & Entertainment
B13: 8K MILES SOFTWARE SERVICES LTD | C13: 512161 | D13: 8KMILES | E13: Internet Software & Services
B14: A & M FEBCON LTD | C14: 540697 | D14: Not Listed | E14: Industrial Machinery
B15: A AND M JUMBO BAGS LTD | C15: Not Listed | D15: AMJUMBO | E15: SME
B16: A INFRASTRUCTURE LTD | C16: 539620 | D16: Not Listed | E16: Cement & Cement Products
B17: A K SPINTEX LTD | C17: 539300 | D17: Not Listed | E17: Textiles
B18: A K CAPITAL SERVICES LTD | C18: 530499 | D18: Not Listed | E18: Finance (including NBFCs)
B19: A.F. Enterprises Ltd | C19: 538351 | D19: AFEL | E19: Investment Companies
B20: A-1 ACID LTD | C20: 542012 | D20: Not Listed | E20: Comm.Trading & Distribution
B21: A2Z INFRA ENGINEERING LTD | C21: 533292 | D21: A2ZINFRA | E21: Utilities:Non-Elec.
B22: AADHAAR VENTURES (INDIA) LTD | C22: 531611 | D22: Not Listed | E22: Finance (including NBFCs)
B23: AADHAAR VENTURES INDIA LTD | C23: 531611 | D23: Not Listed | E23: Finance (including NBFCs)
B24: AAKASH EXPLORATION SERVICES LTD | C24: Not Listed | D24: AAKASH | E24: SME
B25: AANANDA LAKSHMI SPINNING MILLS LTD | C25: 539096 | D25: Not Listed | E25: Textiles
B26: AANCHAL ISPAT LTD | C26: 538812 | D26: Not Listed | E26: Iron & Steel/Interm.Products
B27: AAR COMMERCIAL COMPANY LTD | C27: 539632 | D27: Not Listed | E27: Distributors
B28: Aar Shyam India Investment Company Ltd | C28: 542377 | D28: AARSHYAM | E28: Finance (including NBFCs)
B29: AAREY DRUGS & PHARMACEUTICALS LTD | C29: 524412 | D29: Not Listed | E29: Pharmaceuticals
B30: AARON INDUSTRIES LTD | C30: Not Listed | D30: AARON | E30: SME
B31: Aartech Solonics Ltd | C31: 542580 | D31: AARTECH | E31: Heavy Electrical Equipment
B32: AARTI DRUGS LTD | C32: 524348 | D32: AARTIDRUGS | E32: Pharmaceuticals
B33: AARTI INDUSTRIES LTD | C33: 524208 | D33: AARTIIND | E33: Commodity Chemicals
B34: AARV INFRATEL LTD | C34: 526488 | D34: Not Listed | E34: Textiles
B35: AARVEE DENIMS & EXPORTS LTD | C35: 514274 | D35: AARVEEDEN | E35: Textiles
B36: AARVI ENCON LTD | C36: Not Listed | D36: AARVI | E36: SME
B37: AASHEE INFOTECH LTD | C37: 519319 | D37: Not Listed | E37: Internet Software & Services
B38: AASWA TRADING & EXPORTS LTD | C38: 512038 | D38: Not Listed | E38: Comm.Trading & Distribution
B39: AAVAS FINANCIERS LTD | C39: 541988 | D39: AAVAS | E39: Housing Finance
B40: AAYUSH FOOD AND HERBS LTD | C40: 539528 | D40: Not Listed | E40: Packaged Foods
B41: ABAN OFFSHORE LTD | C41: 523204 | D41: ABAN | E41: Exploration & Production
...

Sheet Football Field
B2: Football Field Analysis - Data
C4: OpenLow | D4: Low | E4: OpenHigh | F4: High
B5: Comps | C5: =D5 -> 967.52777 | D5: ='Comparable Company Valuation'!N28 -> 967.52777 | E5: =F5 -> 1129.0637 | F5: ='Comparable Company Valuation'!P28 -> 1129.0637
B6: DCF Bear | C6: =D6 -> 899.4567 | D6: =DCF!G46 -> 899.4567 | E6: =F6 -> 1293.4127 | F6: =DCF!G50 -> 1293.4127
B7: DCF Base | C7: =D7 -> 988.72502 | D7: =DCF!E46 -> 988.72502 | E7: =F7 -> 1724.5585 | F7: =DCF!E50 -> 1724.5585
B8: DCF Bull | C8: =D8 -> 1142.1556 | D8: =DCF!C46 -> 1142.1556 | E8: =F8 -> 4362.7092 | F8: =DCF!C50 -> 4362.7092
B9: 52 W H/L | C9: =D9 -> 980.4 | D9: 980.4 | E9: =F9 -> 1728 | F9: 1728

Sheet Comparable Company Valuation
B2: Comparable Company Valuation
C4: Market Data | J4: Financials | N4: Valuation
B5: Company | C5: Share Price | D5: Shares Outstanding | E5: Equity Value | F5: Net Debt | G5: Enterprise Value | J5: Revenue | K5: EBITDA | L5: Net Income | N5: EV/Revenue | O5: EV/EBITDA | P5: P/E
B7: Infosys | C7: 1023.4 | D7: ='Income Statement '!H38 -> 405.56 | E7: =C7*D7 -> 415050.1 | F7: ='Balance Sheet'!G7 -> 9176 | G7: 402416.02 | J7: ='Income Statement '!F5 -> 162990 | K7: ='Income Statement '!G17 -> 42280 | L7: ='Income Statement '!G35 -> 26441 | N7: =G7/J7 -> 2.4689614 | O7: =G7/K7 -> 9.5178813 | P7: =E7/L7 -> 15.697217
B8: TCS | C8: 2156 | D8: 363.81 | E8: =C8*D8 -> 784374.36 | F8: 11808 | G8: 777809.67 | J8: 283248 | K8: 18815 | L8: 51858 | N8: =G8/J8 -> 2.7460376 | O8: =G8/K8 -> 41.339871 | P8: =E8/L8 -> 15.125426
B9: HCL Technologies | C9: 1216.7 | D9: 271.37 | E9: =C9*D9 -> 330175.88 | F9: 5215 | G9: 311961.63 | J9: 134374 | K9: 26752 | L9: 17434 | N9: =G9/J9 -> 2.3215922 | O9: =G9/K9 -> 11.661245 | P9: =E9/L9 -> 18.938619
B10: Wipro | C10: 162.57 | D10: 990.53 | E10: =C10*D10 -> 161030.46 | F10: 20291 | G10: 170766.66 | J10: 94968 | K10: 5612.2 | L10: 13285.3 | N10: =G10/J10 -> 1.7981495 | O10: =G10/K10 -> 30.427757 | P10: =E10/L10 -> 12.12095
B11: Tech Mahindra | C11: 1514.1 | D11: 88.63 | E11: =C11*D11 -> 134194.68 | F11: 2186 | G11: 145486.69 | J11: 59176.1 | K11: 2636.1 | L11: 5163 | N11: =G11/J11 -> 2.458538 | O11: =G11/K11 -> 55.190126 | P11: =E11/L11 -> 25.99161
B12: LTM | C12: 4070 | D12: 29.65 | E12: =C12*D12 -> 120675.5 | F12: 2310 | G12: 120222.48 | J12: 44075 | K12: 8649.6 | L12: 5196.7 | N12: =G12/J12 -> 2.7276796 | O12: =G12/K12 -> 13.899195 | P12: =E12/L12 -> 23.221564
B14: High | N14: =MAX(N7:N12) -> 2.7460376 | O14: =MAX(O7:O12) -> 55.190126 | P14: =MAX(P7:P12) -> 25.99161
B15: 75th Percentile | N15: =_xlfn.QUARTILE.EXC(N7:N12,3) -> 2.7322691 | O15: =_xlfn.QUARTILE.EXC(O7:O12,3) -> 44.802435 | P15: =_xlfn.QUARTILE.EXC(P7:P12,3) -> 23.914075
B16: Average | N16: =AVERAGE(N7:N12) -> 2.4201597 | O16: =AVERAGE(O7:O12) -> 27.006013 | P16: =AVERAGE(P7:P12) -> 18.515898
B17: Median | N17: =MEDIAN(N7:N12) -> 2.4637497 | O17: =MEDIAN(O7:O12) -> 22.163476 | P17: =MEDIAN(P7:P12) -> 17.317918
B18: 25th Percentile | N18: =_xlfn.QUARTILE.EXC(N7:N12,1) -> 2.1907315 | O18: =_xlfn.QUARTILE.EXC(O7:O12,1) -> 11.125404 | P18: =_xlfn.QUARTILE.EXC(P7:P12,1) -> 14.374307
B19: Low | N19: =MIN(N7:N12) -> 1.7981495 | O19: =MIN(O7:O12) -> 9.5178813 | P19: =MIN(P7:P12) -> 12.12095
B21: Infosys Comparable Valuation | N21: EV/Revenue | O21: EV/EBITDA | P21: P/E
B23: Implied Enterprise Value | N23: =J7*N17 -> 401566.56 | O23: =K7*O17 -> 937071.78 | P23: =P24+P25 -> 467079.06
B24: Net Debt | N24: =F7 -> 9176 | O24: =N24 -> 9176 | P24: =O24 -> 9176
B25: Implied Market Value | N25: =N23-N24 -> 392390.56 | O25: =O23-O24 -> 927895.78 | P25: =L7*P17 -> 457903.06
B26: Shares Outstanding | N26: =D7 -> 405.56 | O26: =N26 -> 405.56 | P26: =O26 -> 405.56
B28: Implied Value per Share | N28: =N25/N26 -> 967.52777 | O28: =O25/O26 -> 2287.9371 | P28: =P25/P26 -> 1129.0637

Sheet DCF
B2: Discounted Cash Flow
B3: Period | C3: ='Income Statement '!H3 -> 46477 | D3: ='Income Statement '!I3 -> 46842 | E3: ='Income Statement '!J3 -> 47207 | F3: ='Income Statement '!K3 -> 47572 | G3: ='Income Statement '!L3 -> 47937
B5: Free Cash Flows
B7: EBIT | C7: ='Income Statement '!H23 -> 41621.863 | D7: ='Income Statement '!I23 -> 45620.872 | E7: ='Income Statement '!J23 -> 50004.103 | F7: ='Income Statement '!K23 -> 54808.473 | G7: ='Income Statement '!L23 -> 60074.444
B8: Tax | C8: =-'Income Statement '!H23*'Income Statement '!H33 -> -12507.848 | D8: =-'Income Statement '!I23*'Income Statement '!I33 -> -13709.596 | E8: =-'Income Statement '!J23*'Income Statement '!J33 -> -15026.807 | F8: =-'Income Statement '!K23*'Income Statement '!K33 -> -16470.575 | G8: =-'Income Statement '!L23*'Income Statement '!L33 -> -18053.06
B9: D&A | C9: ='Income Statement '!H20 -> 5669.5097 | D9: ='Income Statement '!I20 -> 6214.2334 | E9: ='Income Statement '!J20 -> 6811.2939 | F9: ='Income Statement '!K20 -> 7465.7197 | G9: ='Income Statement '!L20 -> 8183.0225
B10: CapEx | C10: =-'Dep Capex'!H10 -> -13525.907 | D10: =-'Dep Capex'!I10 -> -12566.12 | E10: =-'Dep Capex'!J10 -> -11674.44 | F10: =-'Dep Capex'!K10 -> -10846.032 | G10: =-'Dep Capex'!L10 -> -10076.408
B11: Non-cash Work. Capital (inc) / dec | C11: =-(('Balance Sheet'!H18-'Balance Sheet'!H17-'Balance Sheet'!H8)-('Balance Sheet'!G18-'Balance Sheet'!G17-'Balance Sheet'!G8)) -> 494.28165 | D11: =-(('Balance Sheet'!I18-'Balance Sheet'!I17-'Balance Sheet'!I8)-('Balance Sheet'!H18-'Balance Sheet'!H17-'Balance Sheet'!H8)) -> 1683.3401 | E11: =-(('Balance Sheet'!J18-'Balance Sheet'!J17-'Balance Sheet'!J8)-('Balance Sheet'!I18-'Balance Sheet'!I17-'Balance Sheet'!I8)) -> 1845.0747 | F11: =-(('Balance Sheet'!K18-'Balance Sheet'!K17-'Balance Sheet'!K8)-('Balance Sheet'!J18-'Balance Sheet'!J17-'Balance Sheet'!J8)) -> 2022.3485 | G11: =-(('Balance Sheet'!L18-'Balance Sheet'!L17-'Balance Sheet'!L8)-('Balance Sheet'!K18-'Balance Sheet'!K17-'Balance Sheet'!K8)) -> 2216.6548
B12: FCF | C12: =SUM(C7:C11) -> 21751.901 | D12: =SUM(D7:D11) -> 27242.729 | E12: =SUM(E7:E11) -> 31959.225 | F12: =SUM(F7:F11) -> 36979.934 | G12: =SUM(G7:G11) -> 42344.654
B14: WACC
B16: WACC | C16: =WACC!C21 -> 0.13260882
B18: Terminal Value
B20: Growth rate | G20: 0.04
B21: EBITDA | G21: ='Income Statement '!L17 -> 68257.467
B22: EV/EBITDA Multiple | G22: 8.41
B23: Perpertuity Growth TV | G23: =G12*(1+G20)/(C16-G20) -> 475531.83
B24: EV/ EBITDA TV | G24: =G21*G22 -> 574045.3
B25: Average | G25: =AVERAGE(G23:G24) -> 524788.56
B27: Mid Year Convention | C27: 0.5 | D27: =C27+1 -> 1.5 | E27: =D27+1 -> 2.5 | F27: =E27+1 -> 3.5 | G27: =F27+1 -> 4.5
B29: Discounting Factor | C29: =1/(1+$C$16)^C27 -> 0.93963683 | D29: =1/(1+$C$16)^D27 -> 0.82962168 | E29: =1/(1+$C$16)^E27 -> 0.73248739 | F29: =1/(1+$C$16)^F27 -> 0.64672584 | G29: =1/(1+$C$16)^G27 -> 0.57100548
B30: PV of FCF | C30: =C12*C29 -> 20438.887 | D30: =D12*D29 -> 22601.159 | E30: =E12*E29 -> 23409.729 | F30: =F12*F29 -> 23915.879 | G30: =G12*G29 -> 24179.03
B31: PV of TV | G31: =G25*G29 -> 299657.15
B32: Enterprise Value | C32: =SUM(C30:G31) -> 414201.83
B34: Enterprise Value to Equity Value
B36: Cash | C36: ='Balance Sheet'!G17 -> 22201
B37: Marketable Securities | C37: 0
B38: Debt | C38: ='Balance Sheet'!G7 -> 9176
B39: Equity Value | C39: =C32+C36+C37-C38 -> 427226.83
B41: Shares Outstanding | C41: ='Income Statement '!G38 -> 405.56
B42: Implied Share Price | C42: =C39/C41 -> 1053.4245
B44: Sensitivity Analysis
B45: =C42 -> 1053.4245 | C45: 0.11 | D45: 0.12 | E45: 0.1326 | F45: 0.14 | G45: 0.15
B46: 0.02 | C46: 1142.1556 | D46: 1067.6111 | E46: 988.72502 | F46: 948.3945 | G46: 899.4567
B47: 0.04 | C47: 1257.1753 | D47: 1155.39 | E47: 1053.4879 | F47: 1003.3986 | G47: 944.22443
B48: 0.06 | C48: 1464.2109 | D48: 1301.6883 | E48: 1153.9328 | F48: 1085.9048 | G48: 1008.8889
B49: 0.08 | C49: 1947.294 | D49: 1594.2848 | E49: 1330.7617 | F49: 1223.4151 | G49: 1110.5045
B50: 0.1 | C50: 4362.7092 | D50: 2472.0744 | E50: 1724.5585 | F50: 1498.4357 | G50: 1293.4127

Sheet WACC
B2: Weighted Average Cost of Capital
B4: Name of the Comp | C4: Total Debt | D4: Total Equity | E4: Tax Rate | F4: Risk Free Rate | G4: Beta | H4: Market Return
B6: Infosys | C6: ='Balance Sheet'!H7 -> 9176 | D6: =SUM('Balance Sheet'!H5:H6) -> 102284.51 | E6: ='Income Statement '!G33 -> 0.28464369 | F6: 0.0648 | G6: ='Beta - Regression'!K12 -> 0.77032835 | H6: =RM!F7 -> 0.16449231
B10: Cost of Debt | E10: Cost of Equity
B12: Pre-Tax Cost of Debt | C12: ='Income Statement '!G26/'Balance Sheet'!G7 -> 0.045335658 | E12: Risk Free Rate | H12: =F6 -> 0.0648
B13: Tax Rate | C13: =E6 -> 0.28464369 | E13: Equity Risk Premium | H13: =RM!F7 -> 0.16449231
B14: Post Tax Cost of Debt | C14: =C12*(1-C13) -> 0.032431149 | E14: Levered Beta | H14: =G6 -> 0.77032835
E15: Cost of Equity | H15: =H12+H14*(H13-H12) -> 0.14159581
B17: Weighted Average Cost of Capital
B19: E / D +E | C19: =D6/(D6+C6) -> 0.91767488
B20: D / D+E | C20: =C6/(D6+C6) -> 0.082325118
B21: WACC | C21: =(C19*H15)+(C20*C14) -> 0.13260882

Sheet Beta - Regression
B2: Beta - Regression
B4: Nifty Weekly Returns | F4: Infosys Weekly Returns | I4: Beta Drifting | M4: Beta | N4: =N23 -> 0.69377113
B6: Date | C6: Adj Close | D6: Returns | F6: Adj Close | G6: Returns | I6: Levered Raw Beta | K6: =N4 -> 0.69377113 | M6: SUMMARY OUTPUT
B7: Oct 07, 2024 | C7: 24964.25 | F7: 21.56 | I7: Raw Beta Weight | K7: 0.75
B8: Oct 14, 2024 | C8: 24854.05 | D8: =C8/C7-1 -> -0.0044143125 | F8: 21.16 | G8: =F8/F7-1 -> -0.018552876 | M8: Regression Statistics
B9: Oct 21, 2024 | C9: 24180.8 | D9: =C9/C8-1 -> -0.027088141 | F9: 20.58 | G9: =F9/F8-1 -> -0.027410208 | I9: Market Weight | K9: 1 | M9: Multiple R | N9: 0.28648156
B10: Oct 28, 2024 | C10: 24304.35 | D10: =C10/C9-1 -> 0.0051094257 | F10: 19.74 | G10: =F10/F9-1 -> -0.040816327 | I10: Market Beta Weight | K10: 0.25 | M10: R Square | N10: 0.082071683
B11: Nov 04, 2024 | C11: 24148.2 | D11: =C11/C10-1 -> -0.0064247758 | F11: 20.68 | G11: =F11/F10-1 -> 0.047619048 | M11: Adjusted R Square | N11: 0.073072386
B12: Nov 11, 2024 | C12: 23532.7 | D12: =C12/C11-1 -> -0.025488442 | F12: 20.47 | G12: =F12/F11-1 -> -0.010154739 | I12: Adjusted Beta | K12: =(K6*K7)+(K9*K10) -> 0.77032835 | M12: Standard Error | N12: 0.04219873
B13: Nov 18, 2024 | C13: 23907.25 | D13: =C13/C12-1 -> 0.015916151 | F13: 21.67 | G13: =F13/F12-1 -> 0.058622374 | M13: Observations | N13: 104
B14: Nov 25, 2024 | C14: 24131.1 | D14: =C14/C13-1 -> 0.0093632685 | F14: 20.99 | G14: =F14/F13-1 -> -0.031379788
B15: Dec 02, 2024 | C15: 24677.8 | D15: =C15/C14-1 -> 0.022655411 | F15: 21.74 | G15: =F15/F14-1 -> 0.035731301 | M15: ANOVA
B16: Dec 09, 2024 | C16: 24768.3 | D16: =C16/C15-1 -> 0.0036672637 | F16: 22.25 | G16: =F16/F15-1 -> 0.023459062 | N16: df | O16: SS | P16: MS | Q16: F | R16: Significance F
B17: Dec 16, 2024 | C17: 23587.5 | D17: =C17/C16-1 -> -0.047673841 | F17: 21.61 | G17: =F17/F16-1 -> -0.028764045 | M17: Regression | N17: 1 | O17: 0.016239906 | P17: 0.016239906 | Q17: 9.1197881 | R17: 0.003195286
B18: Dec 23, 2024 | C18: 23813.4 | D18: =C18/C17-1 -> 0.0095771065 | F18: 21.38 | G18: =F18/F17-1 -> -0.010643221 | M18: Residual | N18: 102 | O18: 0.18163475 | P18: 0.0017807328
B19: Dec 30, 2024 | C19: 24004.75 | D19: =C19/C18-1 -> 0.0080353918 | F19: 21.52 | G19: =F19/F18-1 -> 0.0065481759 | M19: Total | N19: 103 | O19: 0.19787465
B20: Jan 06, 2025 | C20: 23431.5 | D20: =C20/C19-1 -> -0.02388069 | F20: 21.59 | G20: =F20/F19-1 -> 0.0032527881
B21: Jan 13, 2025 | C21: 23203.2 | D21: =C21/C20-1 -> -0.0097432943 | F21: 20.15 | G21: =F21/F20-1 -> -0.066697545 | N21: Coefficients | O21: Standard Error | P21: t Stat | Q21: P-value | R21: Lower 95% | S21: Upper 95% | T21: Lower 95.0% | U21: Upper 95.0%
B22: Jan 20, 2025 | C22: 23092.2 | D22: =C22/C21-1 -> -0.0047838229 | F22: 20.62 | G22: =F22/F21-1 -> 0.023325062 | M22: Intercept | N22: -0.0050968877 | O22: 0.0041422965 | P22: -1.2304498 | Q22: 0.22135882 | R22: -0.013313113 | S22: 0.0031193376 | T22: -0.013313113 | U22: 0.0031193376
B23: Jan 27, 2025 | C23: 23482.15 | D23: =C23/C22-1 -> 0.016886654 | F23: 20.87 | G23: =F23/F22-1 -> 0.012124151 | M23: X Variable 1 | N23: 0.69377113 | O23: 0.22973325 | P23: 3.0198987 | Q23: 0.003195286 | R23: 0.23809632 | S23: 1.1494459 | T23: 0.23809632 | U23: 1.1494459
B24: Feb 03, 2025 | C24: 23559.95 | D24: =C24/C23-1 -> 0.0033131549 | F24: 20.76 | G24: =F24/F23-1 -> -0.0052707235
B25: Feb 10, 2025 | C25: 22929.25 | D25: =C25/C24-1 -> -0.026770006 | F25: 20.51 | G25: =F25/F24-1 -> -0.012042389
B26: Feb 17, 2025 | C26: 22795.9 | D26: =C26/C25-1 -> -0.0058157157 | F26: 20.13 | G26: =F26/F25-1 -> -0.018527548
B27: Feb 24, 2025 | C27: 22124.7 | D27: =C27/C26-1 -> -0.029443891 | F27: 19.11 | G27: =F27/F26-1 -> -0.050670641
B28: Mar 03, 2025 | C28: 22552.5 | D28: =C28/C27-1 -> 0.019335855 | F28: 18.89 | G28: =F28/F27-1 -> -0.011512297
B29: Mar 10, 2025 | C29: 22397.2 | D29: =C29/C28-1 -> -0.0068861545 | F29: 17.5 | G29: =F29/F28-1 -> -0.073583907
B30: Mar 17, 2025 | C30: 23350.4 | D30: =C30/C29-1 -> 0.042558891 | F30: 17.42 | G30: =F30/F29-1 -> -0.0045714286
B31: Mar 24, 2025 | C31: 23519.35 | D31: =C31/C30-1 -> 0.0072354221 | F31: 17.28 | G31: =F31/F30-1 -> -0.0080367394
B32: Mar 31, 2025 | C32: 22904.45 | D32: =C32/C31-1 -> -0.02614443 | F32: 15.77 | G32: =F32/F31-1 -> -0.087384259
B33: Apr 07, 2025 | C33: 22828.55 | D33: =C33/C32-1 -> -0.0033137665 | F33: 16.05 | G33: =F33/F32-1 -> 0.017755231
B34: Apr 14, 2025 | C34: 23851.65 | D34: =C34/C33-1 -> 0.044816688 | F34: 15.35 | G34: =F34/F33-1 -> -0.043613707
B35: Apr 21, 2025 | C35: 24039.35 | D35: =C35/C34-1 -> 0.0078694765 | F35: 16.55 | G35: =F35/F34-1 -> 0.078175896
... B111: Oct 05, 2026 | C111: 22520.45 | D111: =C111/C110-1 -> 0.0043930167 | F111: 10.8 | G111: =F111/F110-1 -> -0.02173913

Sheet RM
B2: Returns on Market
B4: Year | C4: Annual
B5: 2000 | C5: -0.1465 | E5: Average Returns | F5: =AVERAGE(C5:C30) -> 0.15149231
B6: 2001 | C6: -0.1618 | E6: Dividend Yield | F6: 0.013
B7: 2002 | C7: 0.0325 | E7: Total Market Returns | F7: =SUM(F5:F6) -> 0.16449231
B8: 2003 | C8: 0.719
B9: 2004 | C9: 0.1068
B10: 2005 | C10: 0.3634
B11: 2006 | C11: 0.3983
B12: 2007 | C12: 0.5477
B13: 2008 | C13: -0.5179
B14: 2009 | C14: 0.7576
B15: 2010 | C15: 0.1795
B16: 2011 | C16: -0.2462
B17: 2012 | C17: 0.277
B18: 2013 | C18: 0.0676
B19: 2014 | C19: 0.3139
... B30: 2025 | C30: 0.1051

Sheet Common Size Statement
B2: ="Common Size Statement-"&'Data Sheet >'!B1 -> Common Size Statement-INFOSYS LTD
B4: Particulers | C4: ='Cash Flow '!C3 -> 44651 | D4: ='Cash Flow '!D3 -> 45016 | E4: ='Cash Flow '!E3 -> 45382 | F4: ='Cash Flow '!F3 -> 45747 | G4: ='Cash Flow '!G3 -> 46112 | H4: ='Cash Flow '!H3 -> 46477 | I4: ='Cash Flow '!I3 -> 46842 | J4: ='Cash Flow '!J3 -> 47207 | ... L4: ='Cash Flow '!L3 -> 47937
B6: ='Income Statement '!B5 -> Sales | C6: ='Income Statement '!C5/'Income Statement '!C5 -> 1 | D6: ='Income Statement '!D5/'Income Statement '!D5 -> 1 | E6: ='Income Statement '!E5/'Income Statement '!E5 -> 1 | F6: ='Income Statement '!F5/'Income Statement '!F5 -> 1 | G6: ='Income Statement '!G5/'Income Statement '!G5 -> 1 | H6: ='Income Statement '!H5/'Income Statement '!H5 -> 1 | I6: ='Income Statement '!I5/'Income Statement '!I5 -> 1 | J6: ='Income Statement '!J5/'Income Statement '!J5 -> 1 | ... L6: ='Income Statement '!L5/'Income Statement '!L5 -> 1
B7: ='Income Statement '!B8 -> COGS | C7: ='Income Statement '!C8/'Income Statement '!C5 -> 0.17117584 | D7: ='Income Statement '!D8/'Income Statement '!D5 -> 0.18059918 | E7: ='Income Statement '!E8/'Income Statement '!E5 -> 0.17826511 | F7: ='Income Statement '!F8/'Income Statement '!F5 -> 0.18784588 | G7: ='Income Statement '!G8/'Income Statement '!G5 -> 0.18553037 | H7: ='Income Statement '!H8/'Income Statement '!H5 -> 0.18068328 | I7: ='Income Statement '!I8/'Income Statement '!I5 -> 0.18068328 | J7: ='Income Statement '!J8/'Income Statement '!J5 -> 0.18068328 | ... L7: ='Income Statement '!L8/'Income Statement '!L5 -> 0.18068328
B8: ='Income Statement '!B14 -> Selling & Other Expenses | C8: ='Income Statement '!C14/'Income Statement '!C5 -> 0.56993941 | D8: ='Income Statement '!D14/'Income Statement '!D5 -> 0.58004184 | E8: ='Income Statement '!E14/'Income Statement '!E5 -> 0.58470098 | F8: ='Income Statement '!F14/'Income Statement '!F5 -> 0.57142769 | G8: ='Income Statement '!G14/'Income Statement '!G5 -> 0.57780577 | H8: ='Income Statement '!H14/'Income Statement '!H5 -> 0.57780577 | I8: ='Income Statement '!I14/'Income Statement '!I5 -> 0.57780577 | J8: ='Income Statement '!J14/'Income Statement '!J5 -> 0.57780577 | ... L8: ='Income Statement '!L14/'Income Statement '!L5 -> 0.57780577
B9: ='Income Statement '!B17 -> EBITDA | C9: ='Income Statement '!C17/'Income Statement '!C5 -> 0.25888475 | D9: ='Income Statement '!D17/'Income Statement '!D5 -> 0.23935898 | E9: ='Income Statement '!E17/'Income Statement '!E5 -> 0.2370339 | F9: ='Income Statement '!F17/'Income Statement '!F5 -> 0.24072642 | G9: ='Income Statement '!G17/'Income Statement '!G5 -> 0.23666387 | H9: ='Income Statement '!H17/'Income Statement '!H5 -> 0.24151096 | I9: ='Income Statement '!I17/'Income Statement '!I5 -> 0.24151096 | J9: ='Income Statement '!J17/'Income Statement '!J5 -> 0.24151096 | ... L9: ='Income Statement '!L17/'Income Statement '!L5 -> 0.24151096
B10: ='Income Statement '!B20 -> Depreciation | C10: ='Income Statement '!C20/'Income Statement '!C5 -> 0.028575891 | D10: ='Income Statement '!D20/'Income Statement '!D5 -> 0.028787125 | E10: ='Income Statement '!E20/'Income Statement '!E5 -> 0.030441856 | F10: ='Income Statement '!F20/'Income Statement '!F5 -> 0.029523284 | G10: ='Income Statement '!G20/'Income Statement '!G5 -> 0.027439127 | H10: ='Income Statement '!H20/'Income Statement '!H5 -> 0.028953457 | I10: ='Income Statement '!I20/'Income Statement '!I5 -> 0.028953457 | J10: ='Income Statement '!J20/'Income Statement '!J5 -> 0.028953457 | ... L10: ='Income Statement '!L20/'Income Statement '!L5 -> 0.028953457
B11: ='Income Statement '!B23 -> EBIT | C11: ='Income Statement '!C23/'Income Statement '!C5 -> 0.23030886 | D11: ='Income Statement '!D23/'Income Statement '!D5 -> 0.21057186 | E11: ='Income Statement '!E23/'Income Statement '!E5 -> 0.20659205 | F11: ='Income Statement '!F23/'Income Statement '!F5 -> 0.21120314 | G11: ='Income Statement '!G23/'Income Statement '!G5 -> 0.20922474 | H11: ='Income Statement '!H23/'Income Statement '!H5 -> 0.2125575 | I11: ='Income Statement '!I23/'Income Statement '!I5 -> 0.2125575 | J11: ='Income Statement '!J23/'Income Statement '!J5 -> 0.2125575 | ... L11: ='Income Statement '!L23/'Income Statement '!L5 -> 0.2125575
B12: ='Income Statement '!B26 -> Interest | C12: ='Income Statement '!C26/'Income Statement '!C5 -> 0.0016441825 | D12: ='Income Statement '!D26/'Income Statement '!D5 -> 0.0019350399 | E12: ='Income Statement '!E26/'Income Statement '!E5 -> 0.003058502 | F12: ='Income Statement '!F26/'Income Statement '!F5 -> 0.0025523038 | G12: ='Income Statement '!G26/'Income Statement '!G5 -> 0.0023285754 | H12: ='Income Statement '!H26/'Income Statement '!H5 -> 0.0018332534 | I12: ='Income Statement '!I26/'Income Statement '!I5 -> 0.0016725552 | J12: ='Income Statement '!J26/'Income Statement '!J5 -> 0.0015259433 | ... L12: ='Income Statement '!L26/'Income Statement '!L5 -> 0.0012701478
B13: ='Income Statement '!B29 -> EBT | C13: ='Income Statement '!C29/'Income Statement '!C5 -> 0.22866468 | D13: ='Income Statement '!D29/'Income Statement '!D5 -> 0.20863682 | E13: ='Income Statement '!E29/'Income Statement '!E5 -> 0.20353355 | F13: ='Income Statement '!F29/'Income Statement '!F5 -> 0.20865084 | G13: ='Income Statement '!G29/'Income Statement '!G5 -> 0.20689617 | H13: ='Income Statement '!H29/'Income Statement '!H5 -> 0.21072425 | I13: ='Income Statement '!I29/'Income Statement '!I5 -> 0.21088495 | J13: ='Income Statement '!J29/'Income Statement '!J5 -> 0.21103156 | ... L13: ='Income Statement '!L29/'Income Statement '!L5 -> 0.21128735
B14: ='Income Statement '!B32 -> Tax | C14: ='Income Statement '!C32/'Income Statement '!C5 -> 0.065471346 | D14: ='Income Statement '!D32/'Income Statement '!D5 -> 0.06277978 | E14: ='Income Statement '!E32/'Income Statement '!E5 -> 0.063382573 | F14: ='Income Statement '!F32/'Income Statement '!F5 -> 0.066617584 | G14: ='Income Statement '!G32/'Income Statement '!G5 -> 0.058891688 | H14: ='Income Statement '!H32/'Income Statement '!H5 -> 0.063325055 | I14: ='Income Statement '!I32/'Income Statement '!I5 -> 0.063373347 | J14: ='Income Statement '!J32/'Income Statement '!J5 -> 0.063417405 | ... L14: ='Income Statement '!L32/'Income Statement '!L5 -> 0.063494275
B15: ='Income Statement '!B35 -> Net Profit | C15: ='Income Statement '!C35/'Income Statement '!C5 -> 0.16319333 | D15: ='Income Statement '!D35/'Income Statement '!D5 -> 0.14585704 | E15: ='Income Statement '!E35/'Income Statement '!E5 -> 0.14015097 | F15: ='Income Statement '!F35/'Income Statement '!F5 -> 0.14203325 | G15: ='Income Statement '!G35/'Income Statement '!G5 -> 0.14800448 | H15: ='Income Statement '!H35/'Income Statement '!H5 -> 0.14739919 | I15: ='Income Statement '!I35/'Income Statement '!I5 -> 0.1475116 | J15: ='Income Statement '!J35/'Income Statement '!J5 -> 0.14761415 | ... L15: ='Income Statement '!L35/'Income Statement '!L5 -> 0.14779308
B17: ="Common Size Statement-"&'Data Sheet >'!B16 -> Common Size Statement-42825
B19: Particulers | C19: =C4 -> 44651 | D19: =D4 -> 45016 | E19: =E4 -> 45382 | F19: =F4 -> 45747 | G19: =G4 -> 46112 | H19: =H4 -> 46477 | I19: =I4 -> 46842 | J19: =J4 -> 47207 | ... L19: =L4 -> 47937
B21: ='Balance Sheet'!B9 -> Total Liabilitis | C21: ='Balance Sheet'!C9/'Balance Sheet'!C9 -> 1 | D21: ='Balance Sheet'!D9/'Balance Sheet'!D9 -> 1 | E21: ='Balance Sheet'!E9/'Balance Sheet'!E9 -> 1 | F21: ='Balance Sheet'!F9/'Balance Sheet'!F9 -> 1 | G21: ='Balance Sheet'!G9/'Balance Sheet'!G9 -> 1 | H21: ='Balance Sheet'!H9/'Balance Sheet'!H9 -> 1 | I21: ='Balance Sheet'!I9/'Balance Sheet'!I9 -> 1 | J21: ='Balance Sheet'!J9/'Balance Sheet'!J9 -> 1 | ... L21: ='Balance Sheet'!L9/'Balance Sheet'!L9 -> 1
B22: ='Balance Sheet'!B5 -> Equity Share Capital | C22: ='Balance Sheet'!C5/'Balance Sheet'!C9 -> 0.017973254 | D22: ='Balance Sheet'!D5/'Balance Sheet'!D9 -> 0.01660567 | E22: ='Balance Sheet'!E5/'Balance Sheet'!E9 -> 0.015225702 | F22: ='Balance Sheet'!F5/'Balance Sheet'!F9 -> 0.014026185 | G22: ='Balance Sheet'!G5/'Balance Sheet'!G9 -> 0.013118324 | H22: ='Balance Sheet'!H5/'Balance Sheet'!H9 -> 0.012194406 | I22: ='Balance Sheet'!I5/'Balance Sheet'!I9 -> 0.011033249 | J22: ='Balance Sheet'!J5/'Balance Sheet'!J9 -> 0.0098981545 | ... L22: ='Balance Sheet'!L5/'Balance Sheet'!L9 -> 0.0078246657
B23: ='Balance Sheet'!B6 -> Reserves | C23: ='Balance Sheet'!C6/'Balance Sheet'!C9 -> 0.627539 | D23: ='Balance Sheet'!D6/'Balance Sheet'!D9 -> 0.58860638 | E23: ='Balance Sheet'!E6/'Balance Sheet'!E9 -> 0.6325908 | F23: ='Balance Sheet'!F6/'Balance Sheet'!F9 -> 0.63429074 | G23: ='Balance Sheet'!G6/'Balance Sheet'!G9 -> 0.58869128 | H23: ='Balance Sheet'!H6/'Balance Sheet'!H9 -> 0.60405997 | I23: ='Balance Sheet'!I6/'Balance Sheet'!I9 -> 0.61320818 | J23: ='Balance Sheet'!J6/'Balance Sheet'!J9 -> 0.62492412 | ... L23: ='Balance Sheet'!L6/'Balance Sheet'!L9 -> 0.65250276
B24: ='Balance Sheet'!B7 -> Borrowings | C24: ='Balance Sheet'!C7/'Balance Sheet'!C9 -> 0.046894945 | D24: ='Balance Sheet'!D7/'Balance Sheet'!D9 -> 0.066607275 | E24: ='Balance Sheet'!E7/'Balance Sheet'!E9 -> 0.061454198 | F24: ='Balance Sheet'!F7/'Balance Sheet'!F9 -> 0.055664941 | G24: ='Balance Sheet'!G7/'Balance Sheet'!G9 -> 0.059473193 | H24: ='Balance Sheet'!H7/'Balance Sheet'!H9 -> 0.055284519 | I24: ='Balance Sheet'!I7/'Balance Sheet'!I9 -> 0.050020302 | J24: ='Balance Sheet'!J7/'Balance Sheet'!J9 -> 0.044874242 | ... L24: ='Balance Sheet'!L7/'Balance Sheet'!L9 -> 0.03547388
B25: ='Balance Sheet'!B8 -> Other Liabilities | C25: ='Balance Sheet'!C8/'Balance Sheet'!C9 -> 0.3075928 | D25: ='Balance Sheet'!D8/'Balance Sheet'!D9 -> 0.32818068 | E25: ='Balance Sheet'!E8/'Balance Sheet'!E9 -> 0.2907293 | F25: ='Balance Sheet'!F8/'Balance Sheet'!F9 -> 0.29601813 | G25: ='Balance Sheet'!G8/'Balance Sheet'!G9 -> 0.3387172 | H25: ='Balance Sheet'!H8/'Balance Sheet'!H9 -> 0.3284611 | I25: ='Balance Sheet'!I8/'Balance Sheet'!I9 -> 0.32573827 | J25: ='Balance Sheet'!J8/'Balance Sheet'!J9 -> 0.32030348 | ... L25: ='Balance Sheet'!L8/'Balance Sheet'!L9 -> 0.3041987
B27: ='Balance Sheet'!B20 -> Total Assets | C27: ='Balance Sheet'!C20/'Balance Sheet'!C20 -> 1 | D27: ='Balance Sheet'!D20/'Balance Sheet'!D20 -> 1 | E27: ='Balance Sheet'!E20/'Balance Sheet'!E20 -> 1 | F27: ='Balance Sheet'!F20/'Balance Sheet'!F20 -> 1 | G27: ='Balance Sheet'!G20/'Balance Sheet'!G20 -> 1 | H27: ='Balance Sheet'!H20/'Balance Sheet'!H20 -> 1 | I27: ='Balance Sheet'!I20/'Balance Sheet'!I20 -> 1 | J27: ='Balance Sheet'!J20/'Balance Sheet'!J20 -> 1 | ... L27: ='Balance Sheet'!L20/'Balance Sheet'!L20 -> 1
B28: ='Balance Sheet'!B10 -> Net Block | C28: ='Balance Sheet'!C10/'Balance Sheet'!C20 -> 0.22102477 | D28: ='Balance Sheet'!D10/'Balance Sheet'!D20 -> 0.23455809 | E28: ='Balance Sheet'!E10/'Balance Sheet'!E20 -> 0.20307308 | F28: ='Balance Sheet'!F10/'Balance Sheet'!F20 -> 0.20948611 | G28: ='Balance Sheet'!G10/'Balance Sheet'!G20 -> 0.21887639 | H28: ='Balance Sheet'!H10/'Balance Sheet'!H20 -> 0.25079504 | I28: ='Balance Sheet'!I10/'Balance Sheet'!I20 -> 0.26153969 | J28: ='Balance Sheet'!J10/'Balance Sheet'!J20 -> 0.25841533 | ... L28: ='Balance Sheet'!L10/'Balance Sheet'!L20 -> 0.22466968
B29: ='Balance Sheet'!B11 -> Capital Work in Progress | C29: ='Balance Sheet'!C11/'Balance Sheet'!C20 -> 0.0035638102 | D29: ='Balance Sheet'!D11/'Balance Sheet'!D20 -> 0.0023114707 | E29: ='Balance Sheet'!E11/'Balance Sheet'!E20 -> 0.002154095 | F29: ='Balance Sheet'!F11/'Balance Sheet'!F20 -> 0.0055076288 | G29: ='Balance Sheet'!G11/'Balance Sheet'!G20 -> 0.0034092088 | H29: ='Balance Sheet'!H11/'Balance Sheet'!H20 -> 0.003592937 | I29: ='Balance Sheet'!I11/'Balance Sheet'!I20 -> 0.0035631528 | J29: ='Balance Sheet'!J11/'Balance Sheet'!J20 -> 0.0035037033 | ... L29: ='Balance Sheet'!L11/'Balance Sheet'!L20 -> 0.0033275379
B30: ='Balance Sheet'!B12 -> Investments | C30: ='Balance Sheet'!C12/'Balance Sheet'!C20 -> 0.17411269 | D30: ='Balance Sheet'!D12/'Balance Sheet'!D20 -> 0.15632926 | E30: ='Balance Sheet'!E12/'Balance Sheet'!E20 -> 0.18102485 | F30: ='Balance Sheet'!F12/'Balance Sheet'!F20 -> 0.15928144 | G30: ='Balance Sheet'!G12/'Balance Sheet'!G20 -> 0.14181271 | H30: ='Balance Sheet'!H12/'Balance Sheet'!H20 -> 0.17152234 | I30: ='Balance Sheet'!I12/'Balance Sheet'!I20 -> 0.17010047 | J30: ='Balance Sheet'!J12/'Balance Sheet'!J20 -> 0.16726243 | ... L30: ='Balance Sheet'!L12/'Balance Sheet'!L20 -> 0.15885251
B31: ='Balance Sheet'!B13 -> Other Assets | C31: ='Balance Sheet'!C13/'Balance Sheet'!C20 -> 0.25716831 | D31: ='Balance Sheet'!D13/'Balance Sheet'!D20 -> 0.30504992 | E31: ='Balance Sheet'!E13/'Balance Sheet'!E20 -> 0.28306867 | F31: ='Balance Sheet'!F13/'Balance Sheet'!F20 -> 0.2494401 | G31: ='Balance Sheet'!G13/'Balance Sheet'!G20 -> 0.26364332 | H31: ='Balance Sheet'!H13/'Balance Sheet'!H20 -> 0.28554657 | I31: ='Balance Sheet'!I13/'Balance Sheet'!I20 -> 0.28317948 | J31: ='Balance Sheet'!J13/'Balance Sheet'!J20 -> 0.27845477 | ... L31: ='Balance Sheet'!L13/'Balance Sheet'!L20 -> 0.26445412
B32: ='Balance Sheet'!B15 -> Receivables | C32: ='Balance Sheet'!C15/'Balance Sheet'!C20 -> 0.19445039 | D32: ='Balance Sheet'!D15/'Balance Sheet'!D20 -> 0.20405149 | E32: ='Balance Sheet'!E15/'Balance Sheet'!E20 -> 0.22197471 | F32: ='Balance Sheet'!F15/'Balance Sheet'!F20 -> 0.21081904 | G32: ='Balance Sheet'!G15/'Balance Sheet'!G20 -> 0.22836514 | H32: ='Balance Sheet'!H15/'Balance Sheet'!H20 -> 0.22290309 | I32: ='Balance Sheet'!I15/'Balance Sheet'!I20 -> 0.2210553 | J32: ='Balance Sheet'!J15/'Balance Sheet'!J20 -> 0.2173671 | ... L32: ='Balance Sheet'!L15/'Balance Sheet'!L20 -> 0.20643793
B33: ='Balance Sheet'!B16 -> Inventory | C33: =IFERROR('Balance Sheet'!C16/'Balance Sheet'!C20,0) -> 0 | D33: =IFERROR('Balance Sheet'!D16/'Balance Sheet'!D20,0) -> 0 | E33: =IFERROR('Balance Sheet'!E16/'Balance Sheet'!E20,0) -> 0 | F33: =IFERROR('Balance Sheet'!F16/'Balance Sheet'!F20,0) -> 0 | G33: =IFERROR('Balance Sheet'!G16/'Balance Sheet'!G20,0) -> 0 | H33: =IFERROR('Balance Sheet'!H16/'Balance Sheet'!H20,0) -> 0 | I33: =IFERROR('Balance Sheet'!I16/'Balance Sheet'!I20,0) -> 0 | J33: =IFERROR('Balance Sheet'!J16/'Balance Sheet'!J20,0) -> 0 | ... L33: =IFERROR('Balance Sheet'!L16/'Balance Sheet'!L20,0) -> 0
B34: ='Balance Sheet'!B17 -> Cash & Bank | C34: ='Balance Sheet'!C17/'Balance Sheet'!C20 -> 0.14968003 | D34: ='Balance Sheet'!D17/'Balance Sheet'!D20 -> 0.097699766 | E34: ='Balance Sheet'!E17/'Balance Sheet'!E20 -> 0.1087046 | F34: ='Balance Sheet'!F17/'Balance Sheet'!F20 -> 0.16546568 | G34: ='Balance Sheet'!G17/'Balance Sheet'!G20 -> 0.14389324 | H34: ='Balance Sheet'!H17/'Balance Sheet'!H20 -> 0.065640028 | I34: ='Balance Sheet'!I17/'Balance Sheet'!I20 -> 0.060561905 | J34: ='Balance Sheet'!J17/'Balance Sheet'!J20 -> 0.074996671 | ... L34: ='Balance Sheet'!L17/'Balance Sheet'!L20 -> 0.14225822

Sheet Ratio Analysis
B2: ="Ratio Analysis-"&'Data Sheet >'!B1 -> Ratio Analysis-INFOSYS LTD
B3: Year | C3: ='Data Sheet >'!G16 -> 44651 | D3: ='Data Sheet >'!H16 -> 45016 | E3: ='Data Sheet >'!I16 -> 45382 | F3: ='Data Sheet >'!J16 -> 45747 | G3: ='Data Sheet >'!K16 -> 46112 | H3: =G3+365 -> 46477 | I3: =H3+365 -> 46842 | J3: =I3+365 -> 47207 | K3: =J3+365 -> 47572 | L3: =K3+365 -> 47937 | M3: Trend | N3: Mean | O3: Median
B5: Sales Growth | D5: ='Income Statement '!D5/'Income Statement '!C5-1 -> 0.20655864 | E5: ='Income Statement '!E5/'Income Statement '!D5-1 -> 0.047033734 | F5: ='Income Statement '!F5/'Income Statement '!E5-1 -> 0.060649444 | G5: ='Income Statement '!G5/'Income Statement '!F5-1 -> 0.096079514 | H5: ='Income Statement '!H5/'Income Statement '!G5-1 -> 0.096079514 | I5: ='Income Statement '!I5/'Income Statement '!H5-1 -> 0.096079514 | J5: ='Income Statement '!J5/'Income Statement '!I5-1 -> 0.096079514 | K5: ='Income Statement '!K5/'Income Statement '!J5-1 -> 0.096079514 | L5: ='Income Statement '!L5/'Income Statement '!K5-1 -> 0.096079514 | N5: =AVERAGE(D5:L5) -> 0.098968767 | O5: =MEDIAN(D5:L5) -> 0.096079514
B6: EBITDA Growth | D6: ='Income Statement '!D17/'Income Statement '!C17-1 -> 0.11555683 | E6: ='Income Statement '!E17/'Income Statement '!D17-1 -> 0.03686308 | F6: ='Income Statement '!F17/'Income Statement '!E17-1 -> 0.077172272 | G6: ='Income Statement '!G17/'Income Statement '!F17-1 -> 0.077581813 | H6: ='Income Statement '!H17/'Income Statement '!G17-1 -> 0.11852822 | I6: ='Income Statement '!I17/'Income Statement '!H17-1 -> 0.096079514 | J6: ='Income Statement '!J17/'Income Statement '!I17-1 -> 0.096079514 | K6: ='Income Statement '!K17/'Income Statement '!J17-1 -> 0.096079514 | L6: ='Income Statement '!L17/'Income Statement '!K17-1 -> 0.096079514 | N6: =AVERAGE(D6:L6) -> 0.090002252 | O6: =MEDIAN(D6:L6) -> 0.096079514
B7: EBIT Growth | D7: ='Income Statement '!D23/'Income Statement '!C23-1 -> 0.10315902 | E7: ='Income Statement '!E23/'Income Statement '!D23-1 -> 0.027244782 | F7: ='Income Statement '!F23/'Income Statement '!E23-1 -> 0.084322928 | G7: ='Income Statement '!G23/'Income Statement '!F23-1 -> 0.085812224 | H7: ='Income Statement '!H23/'Income Statement '!G23-1 -> 0.11353907 | I7: ='Income Statement '!I23/'Income Statement '!H23-1 -> 0.096079514 | J7: ='Income Statement '!J23/'Income Statement '!I23-1 -> 0.096079514 | K7: ='Income Statement '!K23/'Income Statement '!J23-1 -> 0.096079514 | L7: ='Income Statement '!L23/'Income Statement '!K23-1 -> 0.096079514 | N7: =AVERAGE(D7:L7) -> 0.088710676 | O7: =MEDIAN(D7:L7) -> 0.096079514
B8: Net Profit Growth | D8: ='Income Statement '!D35/'Income Statement '!C35-1 -> 0.078383961 | E8: ='Income Statement '!E35/'Income Statement '!D35-1 -> 0.0060727799 | F8: ='Income Statement '!F35/'Income Statement '!E35-1 -> 0.074894368 | G8: ='Income Statement '!G35/'Income Statement '!F35-1 -> 0.14215983 | H8: ='Income Statement '!H35/'Income Statement '!G35-1 -> 0.091596948 | I8: ='Income Statement '!I35/'Income Statement '!H35-1 -> 0.096915384 | J8: ='Income Statement '!J35/'Income Statement '!I35-1 -> 0.096841533 | K8: ='Income Statement '!K35/'Income Statement '!J35-1 -> 0.096774253 | L8: ='Income Statement '!L35/'Income Statement '!K35-1 -> 0.096712953 | N8: =AVERAGE(D8:L8) -> 0.086705778 | O8: =MEDIAN(D8:L8) -> 0.096712953
B9: Dividend Growth | D9: ='Income Statement '!D43/'Income Statement '!C43-1 -> 0.096761529 | E9: ='Income Statement '!E43/'Income Statement '!D43-1 -> 0.35349861 | F9: ='Income Statement '!F43/'Income Statement '!E43-1 -> -0.064855345 | G9: ='Income Statement '!G43/'Income Statement '!F43-1 -> 0.116149 | H9: ='Income Statement '!H43/'Income Statement '!G43-1 -> 0 | I9: ='Income Statement '!I43/'Income Statement '!H43-1 -> 0 | J9: ='Income Statement '!J43/'Income Statement '!I43-1 -> 0 | K9: ='Income Statement '!K43/'Income Statement '!J43-1 -> 0 | L9: ='Income Statement '!L43/'Income Statement '!K43-1 -> 0 | N9: =AVERAGE(D9:L9) -> 0.0557282 | O9: =MEDIAN(D9:L9) -> 0
B11: Gross Margin | C11: ='Income Statement '!C12 -> 0.82882416 | D11: ='Income Statement '!D12 -> 0.81940082 | E11: ='Income Statement '!E12 -> 0.82173489 | F11: ='Income Statement '!F12 -> 0.81215412 | G11: ='Income Statement '!G12 -> 0.81446963 | H11: ='Income Statement '!H12 -> 0.81931672 | I11: ='Income Statement '!I12 -> 0.81931672 | J11: ='Income Statement '!J12 -> 0.81931672 | ... L11: ='Income Statement '!L12 -> 0.81931672 | N11: =AVERAGE(C11:L11) -> 0.81931672 | O11: =MEDIAN(C11:L11) -> 0.81931672
B12: EBITDA Margin | C12: ='Income Statement '!C18 -> 0.25888475 | D12: ='Income Statement '!D18 -> 0.23935898 | E12: ='Income Statement '!E18 -> 0.2370339 | F12: ='Income Statement '!F18 -> 0.24072642 | G12: ='Income Statement '!G18 -> 0.23666387 | H12: ='Income Statement '!H18 -> 0.24151096 | I12: ='Income Statement '!I18 -> 0.24151096 | J12: ='Income Statement '!J18 -> 0.24151096 | ... L12: ='Income Statement '!L18 -> 0.24151096 | N12: =AVERAGE(C12:L12) -> 0.24202227 | O12: =MEDIAN(C12:L12) -> 0.24151096
B13: EBIT Margin | C13: ='Income Statement '!C24 -> 0.23030886 | D13: ='Income Statement '!D24 -> 0.21057186 | E13: ='Income Statement '!E24 -> 0.20659205 | F13: ='Income Statement '!F24 -> 0.21120314 | G13: ='Income Statement '!G24 -> 0.20922474 | H13: ='Income Statement '!H24 -> 0.2125575 | I13: ='Income Statement '!I24 -> 0.2125575 | J13: ='Income Statement '!J24 -> 0.2125575 | ... L13: ='Income Statement '!L24 -> 0.2125575 | N13: =AVERAGE(C13:L13) -> 0.21306882 | O13: =MEDIAN(C13:L13) -> 0.2125575
B14: EBT Margin | C14: ='Income Statement '!C30 -> 0.22866468 | D14: ='Income Statement '!D30 -> 0.20863682 | E14: ='Income Statement '!E30 -> 0.20353355 | F14: ='Income Statement '!F30 -> 0.20865084 | G14: ='Income Statement '!G30 -> 0.20689617 | H14: ='Income Statement '!H30 -> 0.21072425 | I14: ='Income Statement '!I30 -> 0.21088495 | J14: ='Income Statement '!J30 -> 0.21103156 | ... L14: ='Income Statement '!L30 -> 0.21128735 | N14: =AVERAGE(C14:L14) -> 0.21114755 | O14: =MEDIAN(C14:L14) -> 0.2108046
B15: Net Profit Margin | C15: ='Income Statement '!C36 -> 0.16319333 | D15: ='Income Statement '!D36 -> 0.14585704 | E15: ='Income Statement '!E36 -> 0.14015097 | F15: ='Income Statement '!F36 -> 0.14203325 | G15: ='Income Statement '!G36 -> 0.14800448 | H15: ='Income Statement '!H36 -> 0.14739919 | I15: ='Income Statement '!I36 -> 0.1475116 | J15: ='Income Statement '!J36 -> 0.14761415 | ... L15: ='Income Statement '!L36 -> 0.14779308 | N15: =AVERAGE(C15:L15) -> 0.14772648 | O15: =MEDIAN(C15:L15) -> 0.14756288
B17: Sales Expenses%Sales | C17: ='Income Statement '!C15 -> 0.56993941 | D17: ='Income Statement '!D15 -> 0.58004184 | E17: ='Income Statement '!E15 -> 0.58470098 | F17: ='Income Statement '!F15 -> 0.57142769 | G17: ='Income Statement '!G15 -> 0.57780577 | H17: ='Income Statement '!H15 -> 0.57780577 | I17: ='Income Statement '!I15 -> 0.57780577 | J17: ='Income Statement '!J15 -> 0.57780577 | ... L17: ='Income Statement '!L15 -> 0.57780577 | N17: =AVERAGE(C17:L17) -> 0.57729445 | O17: =MEDIAN(C17:L17) -> 0.57780577
B18: Depreciation%Sales | C18: ='Income Statement '!C21 -> 0.028575891 | D18: ='Income Statement '!D21 -> 0.028787125 | E18: ='Income Statement '!E21 -> 0.030441856 | F18: ='Income Statement '!F21 -> 0.029523284 | G18: ='Income Statement '!G21 -> 0.027439127 | H18: ='Income Statement '!H21 -> 0.028953457 | I18: ='Income Statement '!I21 -> 0.028953457 | J18: ='Income Statement '!J21 -> 0.028953457 | ... L18: ='Income Statement '!L21 -> 0.028953457 | N18: =AVERAGE(C18:L18) -> 0.028953457 | O18: =MEDIAN(C18:L18) -> 0.028953457
B19: OperatingIncome%Sales | C19: =C13 -> 0.23030886 | D19: =D13 -> 0.21057186 | E19: =E13 -> 0.20659205 | F19: =F13 -> 0.21120314 | G19: =G13 -> 0.20922474 | H19: =H13 -> 0.2125575 | I19: =I13 -> 0.2125575 | J19: =J13 -> 0.2125575 | ... L19: =L13 -> 0.2125575 | N19: =AVERAGE(C19:L19) -> 0.21306882 | O19: =MEDIAN(C19:L19) -> 0.2125575
B21: Return on Capital Employed | C21: ='Income Statement '!C23/SUM('Balance Sheet'!C5:C7) -> 0.34661734 | D21: ='Income Statement '!D23/SUM('Balance Sheet'!D5:D7) -> 0.3692089 | E21: ='Income Statement '!E23/SUM('Balance Sheet'!E5:E7) -> 0.32906971 | F21: ='Income Statement '!F23/SUM('Balance Sheet'!F5:F7) -> 0.33085684 | G21: ='Income Statement '!G23/SUM('Balance Sheet'!G5:G7) -> 0.36635041 | H21: ='Income Statement '!H23/SUM('Balance Sheet'!H5:H7) -> 0.37342249 | I21: ='Income Statement '!I23/SUM('Balance Sheet'!I5:I7) -> 0.36883147 | J21: ='Income Statement '!J23/SUM('Balance Sheet'!J5:J7) -> 0.35977776 | ... L21: ='Income Statement '!L23/SUM('Balance Sheet'!L5:L7) -> 0.33377961 | N21: =AVERAGE(C21:L21) -> 0.35255903 | O21: =MEDIAN(C21:L21) -> 0.35372677
B22: Retained Earning% | C22: ='Income Statement '!C46 -> 16.267858 | D22: ='Income Statement '!D46 -> 17.687413 | E22: ='Income Statement '!E46 -> 5.9837626 | F22: ='Income Statement '!F46 -> 12.814389 | G22: ='Income Statement '!G46 -> 17.286222 | H22: ='Income Statement '!H46 -> 23.258001 | I22: ='Income Statement '!I46 -> 30.15528 | J22: ='Income Statement '!J46 -> 37.715246 | ... L22: ='Income Statement '!L46 -> 55.084041 | N22: =AVERAGE(C22:L22) -> 26.225378 | O22: =MEDIAN(C22:L22) -> 20.472707
B23: Return on Equity% | C23: ='Income Statement '!C35/SUM('Balance Sheet'!C5:C6) -> 0.26345056 | D23: ='Income Statement '!D35/SUM('Balance Sheet'!D5:D6) -> 0.28388611 | E23: ='Income Statement '!E35/SUM('Balance Sheet'!E5:E6) -> 0.24441645 | F23: ='Income Statement '!F35/SUM('Balance Sheet'!F5:F6) -> 0.24160387 | G23: ='Income Statement '!G35/SUM('Balance Sheet'!G5:G6) -> 0.284765 | H23: ='Income Statement '!H35/SUM('Balance Sheet'!H5:H6) -> 0.28218264 | I23: ='Income Statement '!I35/SUM('Balance Sheet'!I5:I6) -> 0.27647358 | J23: ='Income Statement '!J35/SUM('Balance Sheet'!J5:J6) -> 0.26751539 | ... L23: ='Income Statement '!L35/SUM('Balance Sheet'!L5:L6) -> 0.24454758 | N23: =AVERAGE(C23:L23) -> 0.26453758 | O23: =MEDIAN(C23:L23) -> 0.26548298
